[2023-01-25 14:30:14,476] {taskinstance.py:1159} INFO - Dependencies all met for <TaskInstance: d_1_final_project.insert_district_daily scheduled__2023-01-24T00:00:00+00:00 [queued]>
[2023-01-25 14:30:14,490] {taskinstance.py:1159} INFO - Dependencies all met for <TaskInstance: d_1_final_project.insert_district_daily scheduled__2023-01-24T00:00:00+00:00 [queued]>
[2023-01-25 14:30:14,491] {taskinstance.py:1356} INFO - 
--------------------------------------------------------------------------------
[2023-01-25 14:30:14,492] {taskinstance.py:1357} INFO - Starting attempt 1 of 1
[2023-01-25 14:30:14,493] {taskinstance.py:1358} INFO - 
--------------------------------------------------------------------------------
[2023-01-25 14:30:14,517] {taskinstance.py:1377} INFO - Executing <Task(PythonOperator): insert_district_daily> on 2023-01-24 00:00:00+00:00
[2023-01-25 14:30:14,523] {standard_task_runner.py:52} INFO - Started process 279 to run task
[2023-01-25 14:30:14,528] {standard_task_runner.py:79} INFO - Running: ['***', 'tasks', 'run', 'd_1_final_project', 'insert_district_daily', 'scheduled__2023-01-24T00:00:00+00:00', '--job-id', '105', '--raw', '--subdir', 'DAGS_FOLDER/d_1_final_project.py', '--cfg-path', '/tmp/tmpz3wi70i0', '--error-file', '/tmp/tmp5r5nei_v']
[2023-01-25 14:30:14,530] {standard_task_runner.py:80} INFO - Job 105: Subtask insert_district_daily
[2023-01-25 14:30:14,616] {task_command.py:369} INFO - Running <TaskInstance: d_1_final_project.insert_district_daily scheduled__2023-01-24T00:00:00+00:00 [running]> on host da01296d3c51
[2023-01-25 14:30:14,726] {taskinstance.py:1571} INFO - Exporting the following env vars:
AIRFLOW_CTX_DAG_OWNER=***
AIRFLOW_CTX_DAG_ID=d_1_final_project
AIRFLOW_CTX_TASK_ID=insert_district_daily
AIRFLOW_CTX_EXECUTION_DATE=2023-01-24T00:00:00+00:00
AIRFLOW_CTX_TRY_NUMBER=1
AIRFLOW_CTX_DAG_RUN_ID=scheduled__2023-01-24T00:00:00+00:00
[2023-01-25 14:30:14,918] {logging_mixin.py:115} INFO - GET DATA FROM SQL SUCCESS
[2023-01-25 14:30:14,959] {logging_mixin.py:115} INFO - GET DATA FROM SQL SUCCESS
[2023-01-25 14:30:15,047] {taskinstance.py:1889} ERROR - Task failed with exception
Traceback (most recent call last):
  File "/home/airflow/.local/lib/python3.7/site-packages/airflow/operators/python.py", line 171, in execute
    return_value = self.execute_callable()
  File "/home/airflow/.local/lib/python3.7/site-packages/airflow/operators/python.py", line 189, in execute_callable
    return self.python_callable(*self.op_args, **self.op_kwargs)
  File "/opt/airflow/dags/d_1_final_project.py", line 112, in fun_insert_district_daily
    transformer.create_district_daily()
  File "/opt/airflow/dags/modules/transformer.py", line 111, in create_district_daily
    df_case_dim = self.create_dimension_case()
  File "/opt/airflow/dags/modules/transformer.py", line 72, in create_dimension_case
    df.to_sql(con=self.engine_postgres, name='dim_case',index= False)
  File "/home/airflow/.local/lib/python3.7/site-packages/pandas/core/generic.py", line 2882, in to_sql
    method=method,
  File "/home/airflow/.local/lib/python3.7/site-packages/pandas/io/sql.py", line 728, in to_sql
    **engine_kwargs,
  File "/home/airflow/.local/lib/python3.7/site-packages/pandas/io/sql.py", line 1758, in to_sql
    dtype=dtype,
  File "/home/airflow/.local/lib/python3.7/site-packages/pandas/io/sql.py", line 1650, in prep_table
    table.create()
  File "/home/airflow/.local/lib/python3.7/site-packages/pandas/io/sql.py", line 858, in create
    raise ValueError(f"Table '{self.name}' already exists.")
ValueError: Table 'dim_case' already exists.
[2023-01-25 14:30:15,078] {taskinstance.py:1400} INFO - Marking task as FAILED. dag_id=d_1_final_project, task_id=insert_district_daily, execution_date=20230124T000000, start_date=20230125T143014, end_date=20230125T143015
[2023-01-25 14:30:15,097] {standard_task_runner.py:97} ERROR - Failed to execute job 105 for task insert_district_daily (Table 'dim_case' already exists.; 279)
[2023-01-25 14:30:15,143] {local_task_job.py:156} INFO - Task exited with return code 1
[2023-01-25 14:30:15,210] {local_task_job.py:273} INFO - 0 downstream tasks scheduled from follow-on schedule check
