[2023-01-23 08:17:19,697] {taskinstance.py:1159} INFO - Dependencies all met for <TaskInstance: d_1_final_project.get_data_from_api manual__2023-01-23T08:17:18.221444+00:00 [queued]>
[2023-01-23 08:17:19,710] {taskinstance.py:1159} INFO - Dependencies all met for <TaskInstance: d_1_final_project.get_data_from_api manual__2023-01-23T08:17:18.221444+00:00 [queued]>
[2023-01-23 08:17:19,711] {taskinstance.py:1356} INFO - 
--------------------------------------------------------------------------------
[2023-01-23 08:17:19,712] {taskinstance.py:1357} INFO - Starting attempt 1 of 1
[2023-01-23 08:17:19,713] {taskinstance.py:1358} INFO - 
--------------------------------------------------------------------------------
[2023-01-23 08:17:19,741] {taskinstance.py:1377} INFO - Executing <Task(PythonOperator): get_data_from_api> on 2023-01-23 08:17:18.221444+00:00
[2023-01-23 08:17:19,748] {standard_task_runner.py:52} INFO - Started process 2287 to run task
[2023-01-23 08:17:19,754] {standard_task_runner.py:79} INFO - Running: ['***', 'tasks', 'run', 'd_1_final_project', 'get_data_from_api', 'manual__2023-01-23T08:17:18.221444+00:00', '--job-id', '7', '--raw', '--subdir', 'DAGS_FOLDER/d_1_final_project.py', '--cfg-path', '/tmp/tmpb1a98ts9', '--error-file', '/tmp/tmptbqaaxfy']
[2023-01-23 08:17:19,755] {standard_task_runner.py:80} INFO - Job 7: Subtask get_data_from_api
[2023-01-23 08:17:19,844] {task_command.py:369} INFO - Running <TaskInstance: d_1_final_project.get_data_from_api manual__2023-01-23T08:17:18.221444+00:00 [running]> on host da01296d3c51
[2023-01-23 08:17:19,932] {taskinstance.py:1571} INFO - Exporting the following env vars:
AIRFLOW_CTX_DAG_OWNER=***
AIRFLOW_CTX_DAG_ID=d_1_final_project
AIRFLOW_CTX_TASK_ID=get_data_from_api
AIRFLOW_CTX_EXECUTION_DATE=2023-01-23T08:17:18.221444+00:00
AIRFLOW_CTX_TRY_NUMBER=1
AIRFLOW_CTX_DAG_RUN_ID=manual__2023-01-23T08:17:18.221444+00:00
[2023-01-23 08:17:19,933] {taskinstance.py:1889} ERROR - Task failed with exception
Traceback (most recent call last):
  File "/home/airflow/.local/lib/python3.7/site-packages/airflow/operators/python.py", line 171, in execute
    return_value = self.execute_callable()
  File "/home/airflow/.local/lib/python3.7/site-packages/airflow/operators/python.py", line 189, in execute_callable
    return self.python_callable(*self.op_args, **self.op_kwargs)
  File "/opt/airflow/dags/d_1_final_project.py", line 13, in fun_get_data_from_api
    scraper = CovidScraper(variable.get('url_covid_tracker'))
AttributeError: module '***.models.variable' has no attribute 'get'
[2023-01-23 08:17:19,950] {taskinstance.py:1400} INFO - Marking task as FAILED. dag_id=d_1_final_project, task_id=get_data_from_api, execution_date=20230123T081718, start_date=20230123T081719, end_date=20230123T081719
[2023-01-23 08:17:19,964] {standard_task_runner.py:97} ERROR - Failed to execute job 7 for task get_data_from_api (module '***.models.variable' has no attribute 'get'; 2287)
[2023-01-23 08:17:20,007] {local_task_job.py:156} INFO - Task exited with return code 1
[2023-01-23 08:17:20,059] {local_task_job.py:273} INFO - 0 downstream tasks scheduled from follow-on schedule check
