[2023-01-23 10:19:46,461] {taskinstance.py:1159} INFO - Dependencies all met for <TaskInstance: d_1_final_project.generate_dim manual__2023-01-23T08:21:42.844872+00:00 [queued]>
[2023-01-23 10:19:46,479] {taskinstance.py:1159} INFO - Dependencies all met for <TaskInstance: d_1_final_project.generate_dim manual__2023-01-23T08:21:42.844872+00:00 [queued]>
[2023-01-23 10:19:46,480] {taskinstance.py:1356} INFO - 
--------------------------------------------------------------------------------
[2023-01-23 10:19:46,481] {taskinstance.py:1357} INFO - Starting attempt 19 of 19
[2023-01-23 10:19:46,482] {taskinstance.py:1358} INFO - 
--------------------------------------------------------------------------------
[2023-01-23 10:19:46,504] {taskinstance.py:1377} INFO - Executing <Task(PythonOperator): generate_dim> on 2023-01-23 08:21:42.844872+00:00
[2023-01-23 10:19:46,511] {standard_task_runner.py:52} INFO - Started process 5119 to run task
[2023-01-23 10:19:46,515] {standard_task_runner.py:79} INFO - Running: ['***', 'tasks', 'run', 'd_1_final_project', 'generate_dim', 'manual__2023-01-23T08:21:42.844872+00:00', '--job-id', '57', '--raw', '--subdir', 'DAGS_FOLDER/d_1_final_project.py', '--cfg-path', '/tmp/tmp3eio39r2', '--error-file', '/tmp/tmpubht3hn0']
[2023-01-23 10:19:46,516] {standard_task_runner.py:80} INFO - Job 57: Subtask generate_dim
[2023-01-23 10:19:46,587] {task_command.py:369} INFO - Running <TaskInstance: d_1_final_project.generate_dim manual__2023-01-23T08:21:42.844872+00:00 [running]> on host da01296d3c51
[2023-01-23 10:19:46,676] {taskinstance.py:1571} INFO - Exporting the following env vars:
AIRFLOW_CTX_DAG_OWNER=***
AIRFLOW_CTX_DAG_ID=d_1_final_project
AIRFLOW_CTX_TASK_ID=generate_dim
AIRFLOW_CTX_EXECUTION_DATE=2023-01-23T08:21:42.844872+00:00
AIRFLOW_CTX_TRY_NUMBER=19
AIRFLOW_CTX_DAG_RUN_ID=manual__2023-01-23T08:21:42.844872+00:00
[2023-01-23 10:21:46,743] {taskinstance.py:1889} ERROR - Task failed with exception
Traceback (most recent call last):
  File "/home/airflow/.local/lib/python3.7/site-packages/mysql/connector/connection_cext.py", line 246, in _open_connection
    self._cmysql.connect(**cnx_kwargs)
_mysql_connector.MySQLInterfaceError: Lost connection to MySQL server at 'reading initial communication packet', system error: 0

During handling of the above exception, another exception occurred:

Traceback (most recent call last):
  File "/home/airflow/.local/lib/python3.7/site-packages/sqlalchemy/engine/base.py", line 3141, in _wrap_pool_connect
    return fn()
  File "/home/airflow/.local/lib/python3.7/site-packages/sqlalchemy/pool/base.py", line 301, in connect
    return _ConnectionFairy._checkout(self)
  File "/home/airflow/.local/lib/python3.7/site-packages/sqlalchemy/pool/base.py", line 755, in _checkout
    fairy = _ConnectionRecord.checkout(pool)
  File "/home/airflow/.local/lib/python3.7/site-packages/sqlalchemy/pool/base.py", line 419, in checkout
    rec = pool._do_get()
  File "/home/airflow/.local/lib/python3.7/site-packages/sqlalchemy/pool/impl.py", line 145, in _do_get
    self._dec_overflow()
  File "/home/airflow/.local/lib/python3.7/site-packages/sqlalchemy/util/langhelpers.py", line 72, in __exit__
    with_traceback=exc_tb,
  File "/home/airflow/.local/lib/python3.7/site-packages/sqlalchemy/util/compat.py", line 211, in raise_
    raise exception
  File "/home/airflow/.local/lib/python3.7/site-packages/sqlalchemy/pool/impl.py", line 142, in _do_get
    return self._create_connection()
  File "/home/airflow/.local/lib/python3.7/site-packages/sqlalchemy/pool/base.py", line 247, in _create_connection
    return _ConnectionRecord(self)
  File "/home/airflow/.local/lib/python3.7/site-packages/sqlalchemy/pool/base.py", line 362, in __init__
    self.__connect(first_connect_check=True)
  File "/home/airflow/.local/lib/python3.7/site-packages/sqlalchemy/pool/base.py", line 605, in __connect
    pool.logger.debug("Error on connect(): %s", e)
  File "/home/airflow/.local/lib/python3.7/site-packages/sqlalchemy/util/langhelpers.py", line 72, in __exit__
    with_traceback=exc_tb,
  File "/home/airflow/.local/lib/python3.7/site-packages/sqlalchemy/util/compat.py", line 211, in raise_
    raise exception
  File "/home/airflow/.local/lib/python3.7/site-packages/sqlalchemy/pool/base.py", line 599, in __connect
    connection = pool._invoke_creator(self)
  File "/home/airflow/.local/lib/python3.7/site-packages/sqlalchemy/engine/create.py", line 578, in connect
    return dialect.connect(*cargs, **cparams)
  File "/home/airflow/.local/lib/python3.7/site-packages/sqlalchemy/engine/default.py", line 583, in connect
    return self.dbapi.connect(*cargs, **cparams)
  File "/home/airflow/.local/lib/python3.7/site-packages/mysql/connector/__init__.py", line 272, in connect
    return CMySQLConnection(*args, **kwargs)
  File "/home/airflow/.local/lib/python3.7/site-packages/mysql/connector/connection_cext.py", line 94, in __init__
    self.connect(**kwargs)
  File "/home/airflow/.local/lib/python3.7/site-packages/mysql/connector/abstracts.py", line 1052, in connect
    self._open_connection()
  File "/home/airflow/.local/lib/python3.7/site-packages/mysql/connector/connection_cext.py", line 252, in _open_connection
    sqlstate=exc.sqlstate)
mysql.connector.errors.OperationalError: 2013 (HY000): Lost connection to MySQL server at 'reading initial communication packet', system error: 0

The above exception was the direct cause of the following exception:

Traceback (most recent call last):
  File "/home/airflow/.local/lib/python3.7/site-packages/airflow/operators/python.py", line 171, in execute
    return_value = self.execute_callable()
  File "/home/airflow/.local/lib/python3.7/site-packages/airflow/operators/python.py", line 189, in execute_callable
    return self.python_callable(*self.op_args, **self.op_kwargs)
  File "/opt/airflow/dags/d_1_final_project.py", line 61, in fun_generate_dim
    transformer.get_data_from_mysql()
  File "/opt/airflow/dags/modules/transformer.py", line 12, in get_data_from_mysql
    df = pd.read_sql(sql, con=self.engine_sql)
  File "/home/airflow/.local/lib/python3.7/site-packages/pandas/io/sql.py", line 634, in read_sql
    chunksize=chunksize,
  File "/home/airflow/.local/lib/python3.7/site-packages/pandas/io/sql.py", line 1579, in read_query
    result = self.execute(*args)
  File "/home/airflow/.local/lib/python3.7/site-packages/pandas/io/sql.py", line 1424, in execute
    return self.connectable.execution_options().execute(*args, **kwargs)
  File "<string>", line 2, in execute
  File "/home/airflow/.local/lib/python3.7/site-packages/sqlalchemy/util/deprecations.py", line 390, in warned
    return fn(*args, **kwargs)
  File "/home/airflow/.local/lib/python3.7/site-packages/sqlalchemy/engine/base.py", line 3036, in execute
    connection = self.connect(close_with_result=True)
  File "/home/airflow/.local/lib/python3.7/site-packages/sqlalchemy/engine/base.py", line 3095, in connect
    return self._connection_cls(self, close_with_result=close_with_result)
  File "/home/airflow/.local/lib/python3.7/site-packages/sqlalchemy/engine/base.py", line 91, in __init__
    else engine.raw_connection()
  File "/home/airflow/.local/lib/python3.7/site-packages/sqlalchemy/engine/base.py", line 3174, in raw_connection
    return self._wrap_pool_connect(self.pool.connect, _connection)
  File "/home/airflow/.local/lib/python3.7/site-packages/sqlalchemy/engine/base.py", line 3145, in _wrap_pool_connect
    e, dialect, self
  File "/home/airflow/.local/lib/python3.7/site-packages/sqlalchemy/engine/base.py", line 2004, in _handle_dbapi_exception_noconnection
    sqlalchemy_exception, with_traceback=exc_info[2], from_=e
  File "/home/airflow/.local/lib/python3.7/site-packages/sqlalchemy/util/compat.py", line 211, in raise_
    raise exception
  File "/home/airflow/.local/lib/python3.7/site-packages/sqlalchemy/engine/base.py", line 3141, in _wrap_pool_connect
    return fn()
  File "/home/airflow/.local/lib/python3.7/site-packages/sqlalchemy/pool/base.py", line 301, in connect
    return _ConnectionFairy._checkout(self)
  File "/home/airflow/.local/lib/python3.7/site-packages/sqlalchemy/pool/base.py", line 755, in _checkout
    fairy = _ConnectionRecord.checkout(pool)
  File "/home/airflow/.local/lib/python3.7/site-packages/sqlalchemy/pool/base.py", line 419, in checkout
    rec = pool._do_get()
  File "/home/airflow/.local/lib/python3.7/site-packages/sqlalchemy/pool/impl.py", line 145, in _do_get
    self._dec_overflow()
  File "/home/airflow/.local/lib/python3.7/site-packages/sqlalchemy/util/langhelpers.py", line 72, in __exit__
    with_traceback=exc_tb,
  File "/home/airflow/.local/lib/python3.7/site-packages/sqlalchemy/util/compat.py", line 211, in raise_
    raise exception
  File "/home/airflow/.local/lib/python3.7/site-packages/sqlalchemy/pool/impl.py", line 142, in _do_get
    return self._create_connection()
  File "/home/airflow/.local/lib/python3.7/site-packages/sqlalchemy/pool/base.py", line 247, in _create_connection
    return _ConnectionRecord(self)
  File "/home/airflow/.local/lib/python3.7/site-packages/sqlalchemy/pool/base.py", line 362, in __init__
    self.__connect(first_connect_check=True)
  File "/home/airflow/.local/lib/python3.7/site-packages/sqlalchemy/pool/base.py", line 605, in __connect
    pool.logger.debug("Error on connect(): %s", e)
  File "/home/airflow/.local/lib/python3.7/site-packages/sqlalchemy/util/langhelpers.py", line 72, in __exit__
    with_traceback=exc_tb,
  File "/home/airflow/.local/lib/python3.7/site-packages/sqlalchemy/util/compat.py", line 211, in raise_
    raise exception
  File "/home/airflow/.local/lib/python3.7/site-packages/sqlalchemy/pool/base.py", line 599, in __connect
    connection = pool._invoke_creator(self)
  File "/home/airflow/.local/lib/python3.7/site-packages/sqlalchemy/engine/create.py", line 578, in connect
    return dialect.connect(*cargs, **cparams)
  File "/home/airflow/.local/lib/python3.7/site-packages/sqlalchemy/engine/default.py", line 583, in connect
    return self.dbapi.connect(*cargs, **cparams)
  File "/home/airflow/.local/lib/python3.7/site-packages/mysql/connector/__init__.py", line 272, in connect
    return CMySQLConnection(*args, **kwargs)
  File "/home/airflow/.local/lib/python3.7/site-packages/mysql/connector/connection_cext.py", line 94, in __init__
    self.connect(**kwargs)
  File "/home/airflow/.local/lib/python3.7/site-packages/mysql/connector/abstracts.py", line 1052, in connect
    self._open_connection()
  File "/home/airflow/.local/lib/python3.7/site-packages/mysql/connector/connection_cext.py", line 252, in _open_connection
    sqlstate=exc.sqlstate)
sqlalchemy.exc.OperationalError: (***.connector.errors.OperationalError) 2013 (HY000): Lost connection to MySQL server at 'reading initial communication packet', system error: 0
(Background on this error at: http://sqlalche.me/e/14/e3q8)
[2023-01-23 10:21:46,772] {taskinstance.py:1400} INFO - Marking task as FAILED. dag_id=d_1_final_project, task_id=generate_dim, execution_date=20230123T082142, start_date=20230123T101946, end_date=20230123T102146
[2023-01-23 10:21:46,786] {standard_task_runner.py:97} ERROR - Failed to execute job 57 for task generate_dim ((***.connector.errors.OperationalError) 2013 (HY000): Lost connection to MySQL server at 'reading initial communication packet', system error: 0
(Background on this error at: http://sqlalche.me/e/14/e3q8); 5119)
[2023-01-23 10:21:46,807] {local_task_job.py:156} INFO - Task exited with return code 1
[2023-01-23 10:21:46,863] {local_task_job.py:273} INFO - 0 downstream tasks scheduled from follow-on schedule check
