[2023-01-23 08:52:49,828] {taskinstance.py:1159} INFO - Dependencies all met for <TaskInstance: d_1_final_project.generate_dim manual__2023-01-23T08:21:42.844872+00:00 [queued]>
[2023-01-23 08:52:49,837] {taskinstance.py:1159} INFO - Dependencies all met for <TaskInstance: d_1_final_project.generate_dim manual__2023-01-23T08:21:42.844872+00:00 [queued]>
[2023-01-23 08:52:49,838] {taskinstance.py:1356} INFO - 
--------------------------------------------------------------------------------
[2023-01-23 08:52:49,839] {taskinstance.py:1357} INFO - Starting attempt 6 of 6
[2023-01-23 08:52:49,840] {taskinstance.py:1358} INFO - 
--------------------------------------------------------------------------------
[2023-01-23 08:52:49,867] {taskinstance.py:1377} INFO - Executing <Task(PythonOperator): generate_dim> on 2023-01-23 08:21:42.844872+00:00
[2023-01-23 08:52:49,872] {standard_task_runner.py:52} INFO - Started process 3167 to run task
[2023-01-23 08:52:49,875] {standard_task_runner.py:79} INFO - Running: ['***', 'tasks', 'run', 'd_1_final_project', 'generate_dim', 'manual__2023-01-23T08:21:42.844872+00:00', '--job-id', '35', '--raw', '--subdir', 'DAGS_FOLDER/d_1_final_project.py', '--cfg-path', '/tmp/tmpllzg0w4t', '--error-file', '/tmp/tmp_6rtnx0i']
[2023-01-23 08:52:49,877] {standard_task_runner.py:80} INFO - Job 35: Subtask generate_dim
[2023-01-23 08:52:49,932] {task_command.py:369} INFO - Running <TaskInstance: d_1_final_project.generate_dim manual__2023-01-23T08:21:42.844872+00:00 [running]> on host da01296d3c51
[2023-01-23 08:52:50,006] {taskinstance.py:1571} INFO - Exporting the following env vars:
AIRFLOW_CTX_DAG_OWNER=***
AIRFLOW_CTX_DAG_ID=d_1_final_project
AIRFLOW_CTX_TASK_ID=generate_dim
AIRFLOW_CTX_EXECUTION_DATE=2023-01-23T08:21:42.844872+00:00
AIRFLOW_CTX_TRY_NUMBER=6
AIRFLOW_CTX_DAG_RUN_ID=manual__2023-01-23T08:21:42.844872+00:00
[2023-01-23 08:52:50,081] {taskinstance.py:1889} ERROR - Task failed with exception
Traceback (most recent call last):
  File "/home/airflow/.local/lib/python3.7/site-packages/airflow/operators/python.py", line 171, in execute
    return_value = self.execute_callable()
  File "/home/airflow/.local/lib/python3.7/site-packages/airflow/operators/python.py", line 189, in execute_callable
    return self.python_callable(*self.op_args, **self.op_kwargs)
  File "/opt/airflow/dags/d_1_final_project.py", line 56, in fun_generate_dim
    port=get_conn_postgres.port
  File "/opt/airflow/dags/modules/connector.py", line 15, in connect_postgres
    user, password, host, port, db
  File "<string>", line 2, in create_engine
  File "/home/airflow/.local/lib/python3.7/site-packages/sqlalchemy/util/deprecations.py", line 298, in warned
    return fn(*args, **kwargs)
  File "/home/airflow/.local/lib/python3.7/site-packages/sqlalchemy/engine/create.py", line 522, in create_engine
    entrypoint = u._get_entrypoint()
  File "/home/airflow/.local/lib/python3.7/site-packages/sqlalchemy/engine/url.py", line 653, in _get_entrypoint
    cls = registry.load(name)
  File "/home/airflow/.local/lib/python3.7/site-packages/sqlalchemy/util/langhelpers.py", line 340, in load
    "Can't load plugin: %s:%s" % (self.group, name)
sqlalchemy.exc.NoSuchModuleError: Can't load plugin: sqlalchemy.dialects:***sql.psycopg2
[2023-01-23 08:52:50,117] {taskinstance.py:1400} INFO - Marking task as FAILED. dag_id=d_1_final_project, task_id=generate_dim, execution_date=20230123T082142, start_date=20230123T085249, end_date=20230123T085250
[2023-01-23 08:52:50,132] {standard_task_runner.py:97} ERROR - Failed to execute job 35 for task generate_dim (Can't load plugin: sqlalchemy.dialects:***sql.psycopg2; 3167)
[2023-01-23 08:52:50,169] {local_task_job.py:156} INFO - Task exited with return code 1
[2023-01-23 08:52:50,228] {local_task_job.py:273} INFO - 0 downstream tasks scheduled from follow-on schedule check
